#VRML_SIM R2022a utf8
WorldInfo {
}
Viewpoint {
  orientation -0.33379566038561825 0.02018605923601625 0.9424292971466077 3.0277387937430147
  position 0.759177860919978 -0.054479478257542416 0.6683152601965808
}
TexturedBackground {
}
TexturedBackgroundLight {
}
RectangleArena {
  floorSize 4 4
}
DEF robot_1 Robot {
  translation 0.09958129097157367 0.00033131885100261065 0.053991668755330145
  rotation -0.6206371051123228 -0.7840979424367235 2.059835421381021e-05 0.009718157684919588
  children [
    DEF front_right HingeJoint {
      jointParameters HingeJointParameters {
        position -7.64769442685751e-08
        axis 0 -1 0
        anchor -0.07 0.09 0.01
      }
      device [
        RotationalMotor {
          name "front_right_motor"
        }
      ]
      endPoint Solid {
        translation -0.06999999974906489 0.09 0.013270099999999984
        rotation -0.9999999999999987 3.84419224738839e-08 3.841132275250789e-08 1.5700000000000018
        children [
          DEF wheel_shape Shape {
            geometry Cylinder {
              height 0.04
              radius 0.065
            }
          }
        ]
        name "solid(3)"
        boundingObject USE wheel_shape
        physics Physics {
        }
        locked TRUE
      }
    }
    DEF front_left HingeJoint {
      jointParameters HingeJointParameters {
        position -6.623072076086403e-08
        axis 0 -1 0
        anchor -0.07 -0.09 0.01
      }
      device [
        RotationalMotor {
          name "front_left_motor"
        }
      ]
      endPoint Solid {
        translation -0.07 -0.09 0.01
        rotation -0.999999999999999 3.314182535009852e-08 3.3115444385620383e-08 1.5699999999999894
        children [
          DEF wheel_shape Shape {
            appearance PBRAppearance {
              metalness 0
            }
            geometry Cylinder {
              height 0.04
              radius 0.065
            }
          }
        ]
        name "solid(2)"
        boundingObject USE wheel_shape
        physics Physics {
        }
        locked TRUE
      }
    }
    DEF rear_left HingeJoint {
      jointParameters HingeJointParameters {
        position 1.1465419236519616e-07
        axis 0 -1 0
        anchor 0.07 -0.09 0.01
      }
      device [
        RotationalMotor {
          name "rear_left_motor"
        }
      ]
      endPoint Solid {
        translation 0.07 -0.09 0.01
        rotation -0.9999999999999968 -5.7372681677927446e-08 -5.7327012136914497e-08 1.5700000000000034
        children [
          DEF wheel_shape Shape {
            appearance PBRAppearance {
              metalness 0
            }
            geometry Cylinder {
              height 0.04
              radius 0.065
            }
          }
        ]
        name "solid(1)"
        boundingObject USE wheel_shape
        physics Physics {
        }
        locked TRUE
      }
    }
    DEF rear_right HingeJoint {
      jointParameters HingeJointParameters {
        position -4.404475436145949e-08
        axis 0 -1 0
        anchor 0.07 0.09 0.01
      }
      device [
        RotationalMotor {
          name "rear_right_motor"
        }
      ]
      endPoint Solid {
        translation 0.07000027820324446 0.08999973873843208 0.010041258500114988
        rotation -0.9999999999999996 2.2864592026229572e-08 2.120130538252663e-08 1.5699997524930742
        children [
          DEF wheel_shape Shape {
            appearance PBRAppearance {
              metalness 0
            }
            geometry Cylinder {
              height 0.04
              radius 0.065
            }
          }
        ]
        boundingObject USE wheel_shape
        physics Physics {
        }
        locked TRUE
      }
    }
    DEF robo_shape Shape {
      appearance PBRAppearance {
        baseColor 1 0.33 0.5
        metalness 0
      }
      geometry Box {
        size 0.28 0.14 0.01
      }
    }
  ]
  boundingObject USE robo_shape
  physics Physics {
  }
  controller "my_controller_3_9_7"
  linearVelocity 1.1998108727421147e-08 4.977318466434926e-10 -9.717106937684349e-12
  angularVelocity 2.7396829655832238e-11 -6.648582186361733e-10 -2.310373968605655e-10
}
